Workbook

Sheet Tracker
A1: Praxisphase Tracker
A2: Datum | B2: Beginn | C2: Ende | D2: Dauer | E2: Beschreibung | F2: Notizen für Bericht
A3: 44295 | B3: 44298.635 | C3: 44298.677 | D3: =C3-B3 -> 0.041666667 | E3: NRL Jour Fixe
A4: Vorarbeiten Total | D4: =SUM(D3) -> 0.041666667
A5: 44298 | B5: 44298.458 | C5: 44298.562 | D5: =C5-B5 -> 0.10416667 | E5: Shadertoy Morf2 | F5: xy inside of polygon, Manfred’s Code getestet
B6: 44298.625 | C6: 44298.75 | D6: =C6-B6 -> 0.125 | E6: OpenScad Tutorial
B7: 44298.792 | C7: 44298.854 | D7: =C7-B7 -> 0.0625 | E7: Anruf mit Manfred | F7: Todos: GLSL docu, c++ tutorial zu shader, Parameter aus Shdertoy lesen, Multipass Shader, Mannigfaltigkeit, (Latex, Geos, Box2D)
A8: 44299 | B8: 44299.583 | C8: 44299.75 | D8: =C8-B8 -> 0.16666667 | E8: LearnOpenGL, IDE vorbereiten | F8: Mit Visual Studio 2019 für Mac, XCode, GLFW, CMake, OpenGL, Metal rumgeschlagen
B9: 44299.792 | C9: 44299.854 | D9: =C9-B9 -> 0.0625 | E9: LearnOpenGL, IDE vorbereiten | F9: Xcode für C++ und OpenGL tauglich machen
A10: 44300 | B10: 44300.5 | C10: 44300.542 | D10: =C10-B10 -> 0.041666667 | E10: Mit Moritz über PF auf Minibot geredet
B11: 44300.562 | C11: 44300.646 | D11: =C11-B11 -> 0.083333333 | E11: LearnOpenGL | F11: Tutorial auf PC: Seite 1 - 20 erledigt
B12: 44300.729 | C12: 44300.771 | D12: =C12-B12 -> 0.041666667 | E12: LearnOpenGL | F12: Seite 23, Fenster erzeugt auf PC und Mac
A13: 44301 | B13: 44301.417 | C13: 44301.583 | D13: =C13-B13 -> 0.16666667 | E13: LearnOpenGL | F13: Vertex Shader, Fragment Shader, Tutorial auf Mac und PC bis Seite 34, zwischen drin mit Moritz telefoniert
B14: 44301.688 | C14: 44301.729 | D14: =C14-B14 -> 0.041666667 | E14: Rosen Anruf | F14: Nur kurzer Anruf, wegen schlechter Verbindung verschoben
B15: 44301.729 | C15: 44301.833 | D15: =C15-B15 -> 0.10416667 | E15: LearnOpenGL, Latex | F15: Tutorial bis Seite 37, CLAWAR
A16: 44302 | B16: 44302.333 | C16: 44302.354 | D16: =C16-B16 -> 0.020833333 | E16: Jour Fixe Präzis vorbereitet
B17: 44302.375 | C17: 44302.521 | D17: =C17-B17 -> 0.14583333 | E17: Shadertoy Morf3 | F17: Width, Height, Multishader
B18: 44302.542 | C18: 44302.562 | D18: =C18-B18 -> 0.020833333 | E18: Latex Shop detested, Latex in Atom | F18: https://jinglescode.github.io/2020/04/25/setup-latex-atom/
B19: 44302.562 | C19: 44302.625 | D19: =C19-B19 -> 0.0625 | E19: Shadertoy Morf3 | F19: Energy Funktion versucht
B20: 44302.635 | C20: 44302.684 | D20: =C20-B20 -> 0.048611111 | E20: NRL Jour Fixe
A21: 44304 | B21: 44304.5 | C21: 44304.542 | D21: =C21-B21 -> 0.041666667 | E21: LearnLatex | F21: Latex Basics Angeschaut, Überfolgen
A22: Woche #1 Total | D22: 1.3402778
A23: 44305 | B23: 44305.49 | C23: 44305.542 | D23: =C23-B23 -> 0.052083333 | E23: Besprechung mit Manfred | F23: SVN (SmartSVN, TortoiseSVN), Bilder in Tex (Schwarzweiß und Vektoren), Shader in c++, GNU Plot, Matlab/Scilab, Neue Shader Ideen
B24: 44305.562 | C24: 44305.604 | D24: =C24-B24 -> 0.041666667 | E24: Latex, SVN | F24: auf PC TortoiseSVN und TechLive installiert / getestet
B25: 44305.708 | C25: 44305.854 | D25: =C25-B25 -> 0.14583333 | E25: Shadertoy Morf3 | F25: Energy Formel versucht, Code aufgeräumt,
A26: 44306 | B26: 44306.375 | C26: 44306.458 | D26: =C26-B26 -> 0.083333333 | E26: Shadertoy Morf3 | F26: Energy eingebaut und getestet
B27: 44306.479 | C27: 44306.521 | D27: =C27-B27 -> 0.041666667 | E27: Shadertoy Morf3 | F27: noch mehr an der Energie gefeilt, könnte jetzt passen
B28: 44306.562 | C28: 44306.688 | D28: =C28-B28 -> 0.125 | E28: Shadertoy Morf3 | F28: Scilab Code Verstehen
B29: 44307.708 | C29: 44307.812 | D29: =C29-B29 -> 0.10416667 | E29: LearnLatex | F29: Lektion 1-8 geschafft
A30: 44307 | B30: 44307.417 | C30: 44307.542 | D30: =C30-B30 -> 0.125 | E30: LearnLatex | F30: Lektion 9-13 geschafft
B31: 44307.625 | C31: 44307.74 | D31: =C31-B31 -> 0.11458333 | E31: Shadertoy Morf3 | F31: Hot and Cold, und Color Levels zum konvertieren in SVGs
B32: 44307.875 | C32: 44307.958 | D32: =C32-B32 -> 0.083333333 | E32: Phasenraumbilder und Roboterpose | F32: Interessante Posen gelabelt und Screenshots gemacht, verschiedene Online Tools zum vectorizen getestet (keine gutes dabei)
A33: 44308 | B33: 44308.375 | C33: 44308.458 | D33: =C33-B33 -> 0.083333333 | E33: Shadertoy Morf3 | F33: Grayscale, Bugfixes und Illustrator getestet
A34: 44309 | B34: 44309.375 | C34: 44309.479 | D34: =C34-B34 -> 0.10416667 | E34: TikZ | F34: Seite 30 - 41 (Tutorial 1 angefangen)
B35: 44309.5 | C35: 44309.597 | D35: =C35-B35 -> 0.097222222 | E35: TikZ | F35: Seite 41 - 49 (Tutorial 1 fertig)
B36: 44309.635 | C36: 44309.701 | D36: =C36-B36 -> 0.065972222 | E36: NRL Jour Fixe
A37: 44310 | B37: 44311.667 | C37: 44311.708 | D37: =C37-B37 -> 0.041666667 | E37: TikZ | F37: Seite 50 - 57 (Tutorial 2 angefangen)
A38: 44311 | B38: 44311.667 | C38: 44311.833 | D38: =C38-B38 -> 0.16666667 | E38: TikZ, Roboter Postures | F38: Seite 57 - 61 (Tutorial 2 fertig, Tutorial 3 angefangen)
A39: Woche #2 Total | D39: 1.4756944
A40: 44312 | B40: 44312.333 | C40: 44312.417 | D40: =C40-B40 -> 0.083333333 | E40: Shadertoy Morf3 | F40: Text anzeigen
...

Sheet Zeitplaner
C2: insgesamt | F2: pro Woche
B3: Woche (5T) | C3: Lazy mode | D3: Beast mode | E3: In Echt | F3: Lazy mode | G3: Beast mode | H3: In Echt
B4: 0 | C4: =$B4*$J$32*5 -> 0 | D4: =$B4*$J$34*5 -> 0 | E4: ='Tracker'!D4 -> 0.041666667 | F4: 1.0416667 | G4: 1.5625 | H4: ='Tracker'!D4 -> 0.041666667
B5: 1 | C5: =C4+F5 -> 1.0416667 | D5: =D4+G5 -> 1.5625 | E5: =E4+H5 -> 1.3819444 | F5: 1.0416667 | G5: 1.5625 | H5: ='Tracker'!D22 -> 1.3402778
B6: 2 | C6: =C5+F6 -> 2.0833333 | D6: =D5+G6 -> 3.125 | E6: =E5+H6 -> 2.8576389 | F6: 1.0416667 | G6: 1.5625 | H6: ='Tracker'!D39 -> 1.4756944
B7: 3 | C7: =C6+F7 -> 3.125 | D7: =D6+G7 -> 4.6875 | E7: =E6+H7 -> 4.5069444 | F7: 1.0416667 | G7: 1.5625 | H7: ='Tracker'!D54 -> 1.6493056
B8: 4 | C8: =C7+F8 -> 4.1666667 | D8: =D7+G8 -> 6.25 | E8: =E7+H8 -> 5.7048611 | F8: 1.0416667 | G8: 1.5625 | H8: ='Tracker'!D66 -> 1.1979167
B9: 5 | C9: =C8+F9 -> 5.2083333 | D9: =D8+G9 -> 7.8125 | E9: =E8+H9 -> 7.2638889 | F9: 1.0416667 | G9: 1.5625 | H9: ='Tracker'!D83 -> 1.5590278
B10: 6 | C10: =C9+F10 -> 6.25 | D10: =D9+G10 -> 9.375 | E10: =E9+H10 -> 8.4513889 | F10: 1.0416667 | G10: 1.5625 | H10: ='Tracker'!D$98 -> 1.1875
B11: 7 | C11: =C10+F11 -> 7.2916667 | D11: =D10+G11 -> 10.9375 | E11: =E10+H11 -> 9.8680556 | F11: 1.0416667 | G11: 1.5625 | H11: ='Tracker'!D114 -> 1.4166667
B12: 8 | C12: =C11+F12 -> 8.3333333 | D12: =D11+G12 -> 12.5 | E12: =E11+H12 -> 11.190972 | F12: 1.0416667 | G12: 1.5625 | H12: ='Tracker'!D126 -> 1.3229167
B13: 9 | C13: =C12+F13 -> 9.375 | D13: =D12+G13 -> 14.0625 | E13: =E12+H13 -> 12.444444 | F13: 1.0416667 | G13: 1.5625 | H13: ='Tracker'!D138 -> 1.2534722
B14: 10 | C14: =C13+F14 -> 10.416667 | D14: =D13+G14 -> 15.625 | E14: =E13+H14 -> 12.555556 | F14: 1.0416667 | G14: 1.5625 | H14: ='Tracker'!D$142 -> 0.11111111
B15: 11 | C15: =C14+F15 -> 11.458333 | D15: =D14+G15 -> 17.1875 | E15: =E14+H15 -> 13.819444 | F15: 1.0416667 | G15: 1.5625 | H15: ='Tracker'!D$158 -> 1.2638889
B16: 12 | C16: =C15+F16 -> 12.5 | D16: =D15+G16 -> 18.75 | E16: =E15+H16 -> 15.045139 | F16: 1.0416667 | G16: 1.5625 | H16: ='Tracker'!D$173 -> 1.2256944
B17: 13 | C17: =C16+F17 -> 13.541667 | E17: =E16+H17 -> 16.486111 | F17: 1.0416667 | G17: 1.5625 | H17: ='Tracker'!D$186 -> 1.4409722
B18: 14 | C18: =C17+F18 -> 14.583333 | E18: =E17+H18 -> 17.770833 | F18: 1.0416667 | G18: 1.5625 | H18: ='Tracker'!D$200 -> 1.2847222
B19: 15 | C19: =C18+F19 -> 15.625 | E19: =E18+H19 -> 18.75 | F19: 1.0416667 | G19: 1.5625 | H19: ='Tracker'!D$210 -> 0.97916667
B20: 16 | C20: =C19+F20 -> 16.666667 | F20: 1.0416667 | G20: 1.5625
B21: 17 | C21: =C20+F21 -> 17.708333 | F21: 1.0416667 | G21: 1.5625
B22: 18 | C22: =C21+F22 -> 18.75 | F22: 1.0416667 | G22: 1.5625
B23: Geschafft (%) | E23: 1
B24: Noch übrige Stunden | E24: 0
B25: Übrige Arbeitage (geschätzt) | E25: =E$24*24/'Daily'!D$78*24 -> 0
B26: Übrige Arbeitswochen | E26: =E$25/5 -> 0
I29: Arbeitsstunden Pflicht | J29: 18.75
I30: Maximale # Wochen (Lazy mode) | J30: 18
I31: Lazy mode Tage | J31: =5*J30 -> 90
I32: Lazy mode Stunden/Tag | J32: =J29/J31 -> 0.20833333
I33: Beast mode Tage | J33: 60
I34: Beast mode Stunden/Tag | J34: =J29/J33 -> 0.3125

Sheet Daily
A1: Tägliche Performance
A2: Datum | B2: Lazymode | C2: Beastmode | D2: In Echt | E2: 5 Tage-Schnitt
A3: ='Tracker'!$A5 -> 44298 | B3: 0.20833333 | C3: 0.3125 | D3: 0.29166667
A4: ='Tracker'!$A8 -> 44299 | B4: 0.20833333 | C4: 0.3125 | D4: 0.22916667
A5: 44300 | B5: 0.20833333 | C5: 0.3125 | D5: 0.16666667 | E5: 0.26805556
A6: 44301 | B6: 0.20833333 | C6: 0.3125 | D6: 0.3125 | E6: 0.25763889
A7: 44302 | B7: 0.20833333 | C7: 0.3125 | D7: 0.34027778 | E7: 0.28263889
A8: ='Tracker'!$A23 -> 44305 | B8: 0.20833333 | C8: 0.3125 | D8: 0.23958333 | E8: 0.31388889
A9: 44306 | B9: 0.20833333 | C9: 0.3125 | D9: 0.35416667 | E9: 0.26805556
A10: 44307 | B10: 0.20833333 | C10: 0.3125 | D10: 0.32291667 | E10: 0.29513889
A11: 44308 | B11: 0.20833333 | C11: 0.3125 | D11: ='Tracker'!D33 -> 0.083333333 | E11: 0.27916667
A12: 44309 | B12: 0.20833333 | C12: 0.3125 | D12: 0.47569444 | E12: 0.25763889
A13: 44312 | B13: 0.20833333 | C13: 0.3125 | D13: 0.15972222 | E13: 0.26458333
A14: 44313 | B14: 0.20833333 | C14: 0.3125 | D14: 0.24652778 | E14: 0.33333333
A15: 44314 | B15: 0.20833333 | C15: 0.3125 | D15: 0.35763889 | E15: 0.32986111
A16: 44315 | B16: 0.20833333 | C16: 0.3125 | D16: 0.42708333 | E16: 0.34236111
A17: 44316 | B17: 0.20833333 | C17: 0.3125 | D17: 0.45833333 | E17: 0.34305556
A18: 44319 | B18: 0.20833333 | C18: 0.3125 | D18: 0.22222222 | E18: 0.32361111
A19: 44320 | B19: 0.20833333 | C19: 0.3125 | D19: 0.25 | E19: 0.27986111
A20: 44321 | B20: 0.20833333 | C20: 0.3125 | D20: 0.26041667 | E20: 0.23958333
A21: 44322 | B21: 0.20833333 | C21: 0.3125 | D21: ='Tracker'!D62 -> 0.20833333 | E21: 0.24652778
A22: 44323 | B22: 0.20833333 | C22: 0.3125 | D22: 0.25694444 | E22: 0.26805556
A23: 44326 | B23: 0.20833333 | C23: 0.3125 | D23: 0.25694444 | E23: 0.29097222
A24: 44327 | B24: 0.20833333 | C24: 0.3125 | D24: 0.35763889 | E24: 0.30972222
A25: 44328 | B25: 0.20833333 | C25: 0.3125 | D25: 0.375 | E25: 0.31180556
A26: 44329 | B26: 0.20833333 | C26: 0.3125 | D26: 0.30208333 | E26: 0.30625
A27: 44330 | B27: 0.20833333 | C27: 0.3125 | D27: 0.26736111 | E27: 0.26666667
A28: 44333 | B28: 0.20833333 | C28: 0.3125 | D28: ='Tracker'!D84 -> 0.22916667 | E28: 0.24930556
A29: 44334 | B29: 0.20833333 | C29: 0.3125 | D29: 0.15972222 | E29: 0.24027778
A30: 44335 | B30: 0.20833333 | C30: 0.3125 | D30: 0.28819444 | E30: 0.2375
A31: 44336 | B31: 0.20833333 | C31: 0.3125 | D31: 0.25694444 | E31: 0.24375
A32: 44337 | B32: 0.20833333 | C32: 0.3125 | D32: 0.25347222 | E32: 0.26319444
A33: 44340 | B33: 0.20833333 | C33: 0.3125 | D33: 0.26041667 | E33: 0.26666667
A34: 44341 | B34: 0.20833333 | C34: 0.3125 | D34: 0.25694444 | E34: 0.27777778
A35: 44342 | B35: 0.20833333 | C35: 0.3125 | D35: 0.30555556 | E35: 0.28333333
A36: 44343 | B36: 0.20833333 | C36: 0.3125 | D36: 0.3125 | E36: 0.26597222
A37: 44344 | B37: 0.20833333 | C37: 0.3125 | D37: 0.28125 | E37: 0.27083333
A38: 44347 | B38: 0.20833333 | C38: 0.3125 | D38: 0.17361111 | E38: 0.25972222
A39: 44348 | B39: 0.20833333 | C39: 0.3125 | D39: 0.28125 | E39: 0.25833333
A40: 44349 | B40: 0.20833333 | C40: 0.3125 | D40: ='Tracker'!D120 -> 0.25 | E40: 0.26458333
...
